<?xml version="1.0" ?>
<robot name="HUMAN" xmlns:xacro="http://ros.org/wiki/xacro">
  
  <link name="base_link"/>

  <joint name="base" type="fixed">
    <parent link="base_link"/>
    <child link="HipsLink"/>
    <origin rpy="0 0 0" xyz="0 0 0.987"/>
  </joint>

  <!-- Body Links -->
  <link name="HipsLink">
    <inertial>
      <origin rpy="0 0 0" xyz="-0.0232 0.0 -0.1192"/>
      <mass value="20.9238"/>
      <inertia ixx="-0.3225" ixy="-0.0" ixz="-0.0" iyy="0.0" iyz="0.2362" izz="0.0"/>
    </inertial>
    <visual>
      <origin rpy="0 0 0" xyz="0 0 0"/>
      <geometry>
        <mesh filename="package://human_description/meshes/HipsLinkFull.dae"/>
      </geometry>
    </visual>
    <collision>
      <origin rpy="0 0 0" xyz="0 0 0"/>
      <geometry>
        <mesh filename="package://human_description/meshes/HipsLinkFull.dae"/>
      </geometry>
    </collision>
  </link>

  <link name="TorsoLink">
    <inertial>
      <origin rpy="0 0 0" xyz="-0.1334 0.0 0.4701"/>
      <mass value="10.7790"/>
      <inertia ixx="-0.3481" ixy="-0.0" ixz="-0.0" iyy="0.0" iyz="0.2709" izz="0.0"/>
    </inertial>
    <visual>
      <origin rpy="0 0 0" xyz="0 0 0"/>
      <geometry>
        <mesh filename="package://human_description/meshes/TorsoLinkFull.dae"/>
      </geometry>
    </visual>
    <collision>
      <origin rpy="0 0 0" xyz="0 0 0"/>
      <geometry>
        <mesh filename="package://human_description/meshes/TorsoLinkFull.dae"/>
      </geometry>
    </collision>
  </link>

  <link name="HeadLink">
    <inertial>
      <origin rpy="0 0 0" xyz="0.0459 0.0 0.0433"/>
      <mass value="4.7372"/>
      <inertia ixx="-0.1891" ixy="-0.0" ixz="-0.0" iyy="0.0" iyz="0.1891" izz="0.0"/>
    </inertial>
    <visual>
      <origin rpy="0 0 0" xyz="0 0 0"/>
      <geometry>
        <mesh filename="package://human_description/meshes/HeadLinkFull.dae"/>
      </geometry>
    </visual>
    <collision>
      <origin rpy="0 0 0" xyz="0 0 0"/>
      <geometry>
        <mesh filename="package://human_description/meshes/HeadLinkFull.dae"/>
      </geometry>
    </collision>
  </link>

  <link name="LArmLink">
    <inertial>
      <origin rpy="0 0 0" xyz="-0.0 0.1328 0.0"/>
      <mass value="1.96"/>
      <inertia ixx="-0.3475" ixy="-0.0" ixz="-0.0" iyy="0.0" iyz="0.6719" izz="0.0"/>
    </inertial>
    <visual>
      <origin rpy="0 0 0" xyz="0 0 0"/>
      <geometry>
        <mesh filename="package://human_description/meshes/LArmLinkFull.dae"/>
      </geometry>
    </visual>
    <collision>
      <origin rpy="0 0 0" xyz="0 0 0"/>
      <geometry>
        <mesh filename="package://human_description/meshes/LArmLinkFull.dae"/>
      </geometry>
    </collision>
  </link>

  <link name="LElbowLink">
    <inertial>
      <origin rpy="0 0 0" xyz="0.000513 0.034528 -0.000934"/>
      <mass value="0.25"/>
      <inertia ixx="-5.9e-05" ixy="-0.0" ixz="-0.0" iyy="0.0" iyz="8e-05" izz="0.0"/>
    </inertial>
    <visual>
      <origin rpy="0 0 0" xyz="0 0 0"/>
      <geometry>
        <mesh filename="package://human_description/meshes/LElbowLink.dae"/>
      </geometry>
    </visual>
    <collision>
      <origin rpy="0 0 0" xyz="0 0 0"/>
      <geometry>
        <mesh filename="package://human_description/meshes/LElbowLink.dae"/>
      </geometry>
    </collision>
  </link>

  <link name="LForearmLink">
    <inertial>
      <origin rpy="0 0 0" xyz="-0.0 0.15114 0.0"/>
      <mass value="1.18"/>
      <inertia ixx="-0.0753" ixy="-0.0" ixz="-0.0" iyy="0.0" iyz="0.1326" izz="0.0"/>
    </inertial>
    <visual>
      <origin rpy="0 0 0" xyz="0 0 0"/>
      <geometry>
        <mesh filename="package://human_description/meshes/LForearmLink.dae"/>
      </geometry>
    </visual>
    <collision>
      <origin rpy="0 0 0" xyz="0 0 0"/>
      <geometry>
        <mesh filename="package://human_description/meshes/LForearmLink.dae"/>
      </geometry>
    </collision>
  </link>

  <link name="LHandLink">
    <inertial>
      <origin rpy="0 0 0" xyz="0.0139 0.042 -0.0128"/>
      <mass value="0.272"/>
      <inertia ixx="-0.00029946" ixy="-0.0" ixz="-0.0" iyy="0.0" iyz="0.00019118" izz="0.0"/>
    </inertial>
    <visual>
      <origin rpy="0 0 0" xyz="0 0 0"/>
      <geometry>
        <mesh filename="package://human_description/meshes/LWrist.dae"/>
      </geometry>
    </visual>
    <collision>
      <origin rpy="0 0 0" xyz="0 0 0"/>
      <geometry>
        <mesh filename="package://human_description/meshes/LWrist.dae"/>
      </geometry>
    </collision>
  </link>

  <link name="RArmLink">
    <inertial>
      <origin rpy="0 0 0" xyz="-0.0 -0.1328 0.0"/>
      <mass value="1.96"/>
      <inertia ixx="-0.3475" ixy="-0.0" ixz="-0.0" iyy="0.0" iyz="0.6719" izz="0.0"/>
    </inertial>
    <visual>
      <origin rpy="0 0 0" xyz="0 0 0"/>
      <geometry>
        <mesh filename="package://human_description/meshes/RArmLinkFull.dae"/>
      </geometry>
    </visual>
    <collision>
      <origin rpy="0 0 0" xyz="0 0 0"/>
      <geometry>
        <mesh filename="package://human_description/meshes/RArmLinkFull.dae"/>
      </geometry>
    </collision>
  </link>

  <link name="RElbowLink">
    <inertial>
      <origin rpy="0 0 0" xyz="0.000513 -0.034528 -0.000934"/>
      <mass value="0.25"/>
      <inertia ixx="-5.9e-05" ixy="-0.0" ixz="-0.0" iyy="0.0" iyz="8e-05" izz="0.0"/>
    </inertial>
    <visual>
      <origin rpy="0 0 0" xyz="0 0 0"/>
      <geometry>
        <mesh filename="package://human_description/meshes/RElbowLink.dae"/>
      </geometry>
    </visual>
    <collision>
      <origin rpy="0 0 0" xyz="0 0 0"/>
      <geometry>
        <mesh filename="package://human_description/meshes/RElbowLink.dae"/>
      </geometry>
    </collision>
  </link>

  <link name="RForearmLink">
    <inertial>
      <origin rpy="0 0 0" xyz="-0.0 -0.15114 0.0"/>
      <mass value="1.18"/>
      <inertia ixx="-0.0753" ixy="-0.0" ixz="-0.0" iyy="0.0" iyz="0.1326" izz="0.0"/>
    </inertial>
    <visual>
      <origin rpy="0 0 0" xyz="0 0 0"/>
      <geometry>
        <mesh filename="package://human_description/meshes/RForearmLink.dae"/>
      </geometry>
    </visual>
    <collision>
      <origin rpy="0 0 0" xyz="0 0 0"/>
      <geometry>
        <mesh filename="package://human_description/meshes/RForearmLink.dae"/>
      </geometry>
    </collision>
  </link>

  <link name="RHandLink">
    <inertial>
      <origin rpy="0 0 0" xyz="0.0139 -0.042 -0.0128"/>
      <mass value="0.272"/>
      <inertia ixx="-0.00029946" ixy="-0.0" ixz="-0.0" iyy="0.0" iyz="0.00019118" izz="0.0"/>
    </inertial>
    <visual>
      <origin rpy="0 0 0" xyz="0 0 0"/>
      <geometry>
        <mesh filename="package://human_description/meshes/RWrist.dae"/>
      </geometry>
    </visual>
    <collision>
      <origin rpy="0 0 0" xyz="0 0 0"/>
      <geometry>
        <mesh filename="package://human_description/meshes/RWrist.dae"/>
      </geometry>
    </collision>
  </link>

  <link name="LLegLink">
    <inertial>
      <origin rpy="0 0 0" xyz="-0.0185 -0.0071 -0.178"/>
      <mass value="6.51"/>
      <inertia ixx="-0.1264" ixy="-0.0" ixz="-0.0" iyy="0.0" iyz="0.1264" izz="0.0"/>
    </inertial>
    <visual>
      <origin rpy="0 0 0" xyz="0 0 0"/>
      <geometry>
        <mesh filename="package://human_description/meshes/LLegLink.dae"/>
      </geometry>
    </visual>
    <collision>
      <origin rpy="0 0 0" xyz="0 0 0"/>
      <geometry>
        <mesh filename="package://human_description/meshes/LLegLink.dae"/>
      </geometry>
    </collision>
  </link>

  <link name="LShinLink">
    <inertial>
      <origin rpy="0 0 0" xyz="-0.0131 0.0025 0.0346"/>
      <mass value="3.095"/>
      <inertia ixx="-0.0632" ixy="-0.0" ixz="-0.0" iyy="0.0" iyz="0.0632" izz="0.0"/>
    </inertial>
    <visual>
      <origin rpy="0 0 0" xyz="0 0 0"/>
      <geometry>
        <mesh filename="package://human_description/meshes/LShinLink.dae"/>
      </geometry>
    </visual>
    <collision>
      <origin rpy="0 0 0" xyz="0 0 0"/>
      <geometry>
        <mesh filename="package://human_description/meshes/LShinLink.dae"/>
      </geometry>
    </collision>
  </link>

  <link name="LAnkleLink">
    <inertial>
      <origin rpy="0 0 0" xyz="0.0508 0.0067 -0.0646"/>
      <mass value="0.99"/>
      <inertia ixx="-0.0015" ixy="-0.0" ixz="-0.0" iyy="0.0" iyz="0.0059" izz="0.0"/>
    </inertial>
    <visual>
      <origin rpy="0 0 0" xyz="0 0 0"/>
      <geometry>
        <mesh filename="package://human_description/meshes/LAnkleLinkFull.dae"/>
      </geometry>
    </visual>
    <collision>
      <origin rpy="0 0 0" xyz="0 0 0"/>
      <geometry>
        <mesh filename="package://human_description/meshes/LAnkleLinkFull.dae"/>
      </geometry>
    </collision>
  </link>

  <link name="RLegLink">
    <inertial>
      <origin rpy="0 0 0" xyz="-0.0185 -0.0071 -0.178"/>
      <mass value="6.51"/>
      <inertia ixx="-0.1264" ixy="-0.0" ixz="-0.0" iyy="0.0" iyz="0.1264" izz="0.0"/>
    </inertial>
    <visual>
      <origin rpy="0 0 0" xyz="0 0 0"/>
      <geometry>
        <mesh filename="package://human_description/meshes/RLegLink.dae"/>
      </geometry>
    </visual>
    <collision>
      <origin rpy="0 0 0" xyz="0 0 0"/>
      <geometry>
        <mesh filename="package://human_description/meshes/RLegLink.dae"/>
      </geometry>
    </collision>
  </link>

  <link name="RShinLink">
    <inertial>
      <origin rpy="0 0 0" xyz="-0.0131 0.0025 0.0346"/>
      <mass value="3.095"/>
      <inertia ixx="-0.0632" ixy="-0.0" ixz="-0.0" iyy="0.0" iyz="0.0632" izz="0.0"/>
    </inertial>
    <visual>
      <origin rpy="0 0 0" xyz="0 0 0"/>
      <geometry>
        <mesh filename="package://human_description/meshes/RShinLink.dae"/>
      </geometry>
    </visual>
    <collision>
      <origin rpy="0 0 0" xyz="0 0 0"/>
      <geometry>
        <mesh filename="package://human_description/meshes/RShinLink.dae"/>
      </geometry>
    </collision>
  </link>

  <link name="RAnkleLink">
    <inertial>
      <origin rpy="0 0 0" xyz="0.0508 -0.0067 -0.0646"/>
      <mass value="0.99"/>
      <inertia ixx="-0.0015" ixy="-0.0" ixz="-0.0" iyy="0.0" iyz="0.0059" izz="0.0"/>
    </inertial>
    <visual>
      <origin rpy="0 0 0" xyz="0 0 0"/>
      <geometry>
        <mesh filename="package://human_description/meshes/RAnkleLinkFull.dae"/>
      </geometry>
    </visual>
    <collision>
      <origin rpy="0 0 0" xyz="0 0 0"/>
      <geometry>
        <mesh filename="package://human_description/meshes/RAnkleLinkFull.dae"/>
      </geometry>
    </collision>
  </link>

  <!-- Joints -->

  <!-- Hips to Torso : spherical -->
  <link name="hip2torso_1">
    <inertial>
      <origin rpy="0 0 0" xyz="0.0 0.0 0.0"/>
      <mass value="0.2"/>
      <inertia ixx="0.0000032" ixy="0.0" ixz="0.0" iyy="0.0000032" iyz="0.0" izz="0.0000032"/>
    </inertial>
    <visual>
      <geometry>
        <sphere radius="0.02"/>
      </geometry>
    </visual>
    <collision>
      <geometry>
        <sphere radius="0.02"/>
      </geometry>
    </collision>
  </link>

  <link name="hip2torso_2">
    <inertial>
      <origin rpy="0 0 0" xyz="0.0 0.0 0.0"/>
      <mass value="0.2"/>
      <inertia ixx="0.0000032" ixy="0.0" ixz="0.0" iyy="0.0000032" iyz="0.0" izz="0.0000032"/>
    </inertial>
    <visual>
      <geometry>
        <sphere radius="0.02"/>
      </geometry>
    </visual>
    <collision>
      <geometry>
        <sphere radius="0.02"/>
      </geometry>
    </collision>
  </link>

  <joint name="Torso_0" type="revolute">
    <parent link="HipsLink"/>
    <child link="hip2torso_1"/>
    <origin rpy="0.0 0.0 0.0" xyz="-0.0 0.0 0.0"/>
    <axis xyz="1 0 0"/>
    <limit effort="100" lower="-0.65" upper="0.65" velocity="100"/>
  </joint>

  <joint name="Torso_1" type="revolute">
    <parent link="hip2torso_1"/>
    <child link="hip2torso_2"/>
    <origin rpy="0.0 0.0 0.0" xyz="-0.0 0.0 0.0"/>
    <axis xyz="0 1 0"/>
    <limit effort="100" lower="-0.55" upper="2.9" velocity="100"/>
  </joint>

  <joint name="Torso_2" type="revolute">
    <parent link="hip2torso_2"/>
    <child link="TorsoLink"/>
    <origin rpy="0.0 0.0 0.0" xyz="-0.0 0.0 0.0"/>
    <axis xyz="0 0 1"/>
    <limit effort="100" lower="-0.7" upper="0.7" velocity="100"/>
  </joint>

  <!-- Torso to Head : spherical -->
  <link name="torso2head_1">
    <inertial>
      <origin rpy="0 0 0" xyz="0.0 0.0 0.0"/>
      <mass value="0.05"/>
      <inertia ixx="0.000002" ixy="0.0" ixz="0.0" iyy="0.000002" iyz="0.0" izz="0.000002"/>
    </inertial>
    <visual>
      <geometry>
        <sphere radius="0.01"/>
      </geometry>
    </visual>
    <collision>
      <geometry>
        <sphere radius="0.01"/>
      </geometry>
    </collision>
  </link>

  <link name="torso2head_2">
    <inertial>
      <origin rpy="0 0 0" xyz="0.0 0.0 0.0"/>
      <mass value="0.05"/>
      <inertia ixx="0.000002" ixy="0.0" ixz="0.0" iyy="0.000002" iyz="0.0" izz="0.000002"/>
    </inertial>
    <visual>
      <geometry>
        <sphere radius="0.01"/>
      </geometry>
    </visual>
    <collision>
      <geometry>
        <sphere radius="0.01"/>
      </geometry>
    </collision>
  </link>

  <joint name="Head_0" type="revolute">
    <parent link="TorsoLink"/>
    <child link="torso2head_1"/>
    <origin rpy="0.0 0.0 0.0" xyz="-0.025 0.0 0.525"/>
    <axis xyz="1 0 0"/>
    <limit effort="100" lower="-0.62" upper="0.62" velocity="100"/>
  </joint>

  <joint name="Head_1" type="revolute">
    <parent link="torso2head_1"/>
    <child link="torso2head_2"/>
    <origin rpy="0.0 0.0 0.0" xyz="-0.0 0.0 0.0"/>
    <axis xyz="0 1 0"/>
    <limit effort="100" lower="-0.45" upper="0.45" velocity="100"/>
  </joint>

  <joint name="Head_2" type="revolute">
    <parent link="torso2head_2"/>
    <child link="HeadLink"/>
    <origin rpy="0.0 0.0 0.0" xyz="-0.0 0.0 0.0"/>
    <axis xyz="0 0 1"/>
    <limit effort="100" lower="-1.1" upper="1.1" velocity="100"/>
  </joint>

  <!-- Torso to left Shoulder : spherical -->
  <link name="torso2lshoulder_1">
    <inertial>
      <origin rpy="0 0 0" xyz="0.0 0.0 0.0"/>
      <mass value="0.2"/>
      <inertia ixx="0.0000032" ixy="0.0" ixz="0.0" iyy="0.0000032" iyz="0.0" izz="0.0000032"/>
    </inertial>
    <visual>
      <geometry>
        <sphere radius="0.02"/>
      </geometry>
    </visual>
    <collision>
      <geometry>
        <sphere radius="0.02"/>
      </geometry>
    </collision>
  </link>

  <link name="torso2lshoulder_2">
    <inertial>
      <origin rpy="0 0 0" xyz="0.0 0.0 0.0"/>
      <mass value="0.2"/>
      <inertia ixx="0.0000032" ixy="0.0" ixz="0.0" iyy="0.0000032" iyz="0.0" izz="0.0000032"/>
    </inertial>
    <visual>
      <geometry>
        <sphere radius="0.02"/>
      </geometry>
    </visual>
    <collision>
      <geometry>
        <sphere radius="0.02"/>
      </geometry>
    </collision>
  </link>

  <joint name="LArm_0" type="revolute">
    <parent link="TorsoLink"/>
    <child link="torso2lshoulder_1"/>
    <origin rpy="0.0 0.0 0.0" xyz="-0.05 0.15 0.35"/>
    <axis xyz="1 0 0"/>
    <limit effort="100" lower="-1.42" upper="1.57" velocity="100"/>
  </joint>

  <joint name="LArm_1" type="revolute">
    <parent link="torso2lshoulder_1"/>
    <child link="torso2lshoulder_2"/>
    <origin rpy="0.0 0.0 0.0" xyz="-0.0 0.0 0.0"/>
    <axis xyz="0 1 0"/>
    <limit effort="100" lower="-1.2" upper="1.2" velocity="100"/>
  </joint>

  <joint name="LArm_2" type="revolute">
    <parent link="torso2lshoulder_2"/>
    <child link="LArmLink"/>
    <origin rpy="0.0 0.0 0.0" xyz="-0.0 0.0 0.0"/>
    <axis xyz="0 0 1"/>
    <limit effort="100" lower="-2.25" upper="0.78" velocity="100"/>
  </joint>


  <joint name="LElbow" type="revolute">
    <parent link="LArmLink"/>
    <child link="LElbowLink"/>
    <origin rpy="0.0 0.0 0.0" xyz="-0.0 0.2 0.0"/>
    <axis xyz="0 1 0"/>
    <limit effort="100" lower="-1.57" upper="1.0" velocity="100"/>
  </joint>


  <joint name="LForearm" type="revolute">
    <parent link="LElbowLink"/>
    <child link="LForearmLink"/>
    <origin rpy="0.0 0.0 0.0" xyz="-0.01 0.05 0.0"/>
    <axis xyz="0 0 1"/>
    <limit effort="100" lower="-2.5" upper="0.0" velocity="100"/>
  </joint>


  <!-- Forearm to left Wrist connection-->
  <link name="forearm2lwrist_1">
    <inertial>
      <origin rpy="0 0 0" xyz="0.0 0.0 0.0"/>
      <mass value="0.05"/>
      <inertia ixx="0.000002" ixy="0.0" ixz="0.0" iyy="0.000002" iyz="0.0" izz="0.000002"/>
    </inertial>
    <visual>
      <geometry>
        <sphere radius="0.01"/>
      </geometry>
    </visual>
    <collision>
      <geometry>
        <sphere radius="0.01"/>
      </geometry>
    </collision>
  </link>

  <joint name="LWrist_0" type="revolute">
    <parent link="LForearmLink"/>
    <child link="forearm2lwrist_1"/>
    <origin rpy="0.0 0.0 0.0" xyz="0.01 0.24 -0.01"/>
    <axis xyz="1 0 0"/>
    <limit effort="100" lower="-1.5" upper="1.5" velocity="100"/>
  </joint>

  <joint name="LWrist_1" type="revolute">
    <parent link="forearm2lwrist_1"/>
    <child link="LHandLink"/>
    <origin rpy="0.0 0.0 0.0" xyz="0.0 0.0 0.0"/>
    <axis xyz="0 0 1"/>
    <limit effort="100" lower="-0.35" upper="0.35" velocity="100"/>
  </joint>


  <!-- Torso to right Shoulder : spherical -->
  <link name="torso2rshoulder_1">
    <inertial>
      <origin rpy="0 0 0" xyz="0.0 0.0 0.0"/>
      <mass value="0.2"/>
      <inertia ixx="0.0000032" ixy="0.0" ixz="0.0" iyy="0.0000032" iyz="0.0" izz="0.0000032"/>
    </inertial>
    <visual>
      <geometry>
        <sphere radius="0.02"/>
      </geometry>
    </visual>
    <collision>
      <geometry>
        <sphere radius="0.02"/>
      </geometry>
    </collision>
  </link>

  <link name="torso2rshoulder_2">
    <inertial>
      <origin rpy="0 0 0" xyz="0.0 0.0 0.0"/>
      <mass value="0.2"/>
      <inertia ixx="0.0000032" ixy="0.0" ixz="0.0" iyy="0.0000032" iyz="0.0" izz="0.0000032"/>
    </inertial>
    <visual>
      <geometry>
        <sphere radius="0.02"/>
      </geometry>
    </visual>
    <collision>
      <geometry>
        <sphere radius="0.02"/>
      </geometry>
    </collision>
  </link>

  <joint name="RArm_0" type="revolute">
    <parent link="TorsoLink"/>
    <child link="torso2rshoulder_1"/>
    <origin rpy="0.0 0.0 0.0" xyz="-0.05 -0.15 0.35"/>
    <axis xyz="1 0 0"/>
    <limit effort="100" lower="-1.42" upper="1.57" velocity="100"/>
  </joint>

  <joint name="RArm_1" type="revolute">
    <parent link="torso2rshoulder_1"/>
    <child link="torso2rshoulder_2"/>
    <origin rpy="0.0 0.0 0.0" xyz="-0.0 0.0 0.0"/>
    <axis xyz="0 1 0"/>
    <limit effort="100" lower="-1.2" upper="1.2" velocity="100"/>
  </joint>

  <joint name="RArm_2" type="revolute">
    <parent link="torso2rshoulder_2"/>
    <child link="RArmLink"/>
    <origin rpy="0.0 0.0 0.0" xyz="-0.0 0.0 0.0"/>
    <axis xyz="0 0 1"/>
    <limit effort="100" lower="-2.25" upper="0.78" velocity="100"/>
  </joint>


  <joint name="RElbow" type="revolute">
    <parent link="RArmLink"/>
    <child link="RElbowLink"/>
    <origin rpy="0.0 0.0 0.0" xyz="-0.0 -0.2 0.0"/>
    <axis xyz="0 1 0"/>
    <limit effort="100" lower="-1.57" upper="1.0" velocity="100"/>
  </joint>


  <joint name="RForearm" type="revolute">
    <parent link="RElbowLink"/>
    <child link="RForearmLink"/>
    <origin rpy="0.0 0.0 0.0" xyz="-0.01 -0.05 0.0"/>
    <axis xyz="0 0 1"/>
    <limit effort="100" lower="0.0" upper="2.5" velocity="100"/>
  </joint>


  <!-- Forearm to right Wrist connection-->
  <link name="forearm2rwrist_1">
    <inertial>
      <origin rpy="0 0 0" xyz="0.0 0.0 0.0"/>
      <mass value="0.05"/>
      <inertia ixx="0.000002" ixy="0.0" ixz="0.0" iyy="0.000002" iyz="0.0" izz="0.000002"/>
    </inertial>
    <visual>
      <geometry>
        <sphere radius="0.01"/>
      </geometry>
    </visual>
    <collision>
      <geometry>
        <sphere radius="0.01"/>
      </geometry>
    </collision>
  </link>

  <joint name="RWrist_0" type="revolute">
    <parent link="RForearmLink"/>
    <child link="forearm2rwrist_1"/>
    <origin rpy="0.0 0.0 0.0" xyz="0.01 -0.24 -0.01"/>
    <axis xyz="1 0 0"/>
    <limit effort="100" lower="-1.5" upper="1.5" velocity="100"/>
  </joint>

  <joint name="RWrist_1" type="revolute">
    <parent link="forearm2rwrist_1"/>
    <child link="RHandLink"/>
    <origin rpy="0.0 0.0 0.0" xyz="0.0 0.0 0.0"/>
    <axis xyz="0 0 1"/>
    <limit effort="100" lower="-0.35" upper="0.35" velocity="100"/>
  </joint>


  <!-- Torso to left Leg : spherical -->
  <link name="torso2lleg_1">
    <inertial>
      <origin rpy="0 0 0" xyz="0.0 0.0 0.0"/>
      <mass value="0.2"/>
      <inertia ixx="0.0000032" ixy="0.0" ixz="0.0" iyy="0.0000032" iyz="0.0" izz="0.0000032"/>
    </inertial>
    <visual>
      <geometry>
        <sphere radius="0.02"/>
      </geometry>
    </visual>
    <collision>
      <geometry>
        <sphere radius="0.02"/>
      </geometry>
    </collision>
  </link>

  <link name="torso2lleg_2">
    <inertial>
      <origin rpy="0 0 0" xyz="0.0 0.0 0.0"/>
      <mass value="0.2"/>
      <inertia ixx="0.0000032" ixy="0.0" ixz="0.0" iyy="0.0000032" iyz="0.0" izz="0.0000032"/>
    </inertial>
    <visual>
      <geometry>
        <sphere radius="0.02"/>
      </geometry>
    </visual>
    <collision>
      <geometry>
        <sphere radius="0.02"/>
      </geometry>
    </collision>
  </link>

  <joint name="LLeg_0" type="revolute">
    <parent link="HipsLink"/>
    <child link="torso2lleg_1"/>
    <origin rpy="0.0 0.0 0.0" xyz="-0.0 0.1 -0.15"/>
    <axis xyz="1 0 0"/>
    <limit effort="100" lower="-0.52" upper="0.87" velocity="100"/>
  </joint>

  <joint name="LLeg_1" type="revolute">
    <parent link="torso2lleg_1"/>
    <child link="torso2lleg_2"/>
    <origin rpy="0.0 0.0 0.0" xyz="0.0 0.0 0.0"/>
    <axis xyz="0 1 0"/>
    <limit effort="100" lower="-2.3" upper="0.52" velocity="100"/>
  </joint>

  <joint name="LLeg_2" type="revolute">
    <parent link="torso2lleg_2"/>
    <child link="LLegLink"/>
    <origin rpy="0.0 0.0 0.0" xyz="0.0 0.0 0.0"/>
    <axis xyz="0 0 1"/>
    <limit effort="100" lower="-0.8" upper="0.8" velocity="100"/>
  </joint>


  <joint name="LShin_0" type="revolute">
    <parent link="LLegLink"/>
    <child link="LShinLink"/>
    <origin rpy="0.0 0.0 0.0" xyz="-0.025 0.0 -0.35"/>
    <axis xyz="0 1 0"/>
    <limit effort="100" lower="0.0" upper="2.6" velocity="100"/>
  </joint>

  <!-- Shin to left Ankle : 2DoF -->
  <link name="shin2lankle_1">
    <inertial>
      <origin rpy="0 0 0" xyz="0.0 0.0 0.0"/>
      <mass value="0.2"/>
      <inertia ixx="0.0000032" ixy="0.0" ixz="0.0" iyy="0.0000032" iyz="0.0" izz="0.0000032"/>
    </inertial>
    <visual>
      <geometry>
        <sphere radius="0.02"/>
      </geometry>
    </visual>
    <collision>
      <geometry>
        <sphere radius="0.02"/>
      </geometry>
    </collision>
  </link>

  <joint name="LAnkle_0" type="revolute">
    <parent link="LShinLink"/>
    <child link="shin2lankle_1"/>
    <origin rpy="0.0 0.0 0.0" xyz="-0.025 0.0 -0.375"/>
    <axis xyz="0 1 0"/>
    <limit effort="100" lower="-0.78" upper="1.3" velocity="100"/>
  </joint>

  <joint name="LAnkle_1" type="revolute">
    <parent link="shin2lankle_1"/>
    <child link="LAnkleLink"/>
    <origin rpy="0.0 0.0 0.0" xyz="0.0 0.0 0.0"/>
    <axis xyz="1 0 0"/>
    <limit effort="100" lower="-0.5" upper="0.5" velocity="100"/>
  </joint>


  <!-- Torso to right Leg : spherical -->
  <link name="torso2rleg_1">
    <inertial>
      <origin rpy="0 0 0" xyz="0.0 0.0 0.0"/>
      <mass value="0.2"/>
      <inertia ixx="0.0000032" ixy="0.0" ixz="0.0" iyy="0.0000032" iyz="0.0" izz="0.0000032"/>
    </inertial>
    <visual>
      <geometry>
        <sphere radius="0.02"/>
      </geometry>
    </visual>
    <collision>
      <geometry>
        <sphere radius="0.02"/>
      </geometry>
    </collision>
  </link>

  <link name="torso2rleg_2">
    <inertial>
      <origin rpy="0 0 0" xyz="0.0 0.0 0.0"/>
      <mass value="0.2"/>
      <inertia ixx="0.0000032" ixy="0.0" ixz="0.0" iyy="0.0000032" iyz="0.0" izz="0.0000032"/>
    </inertial>
    <visual>
      <geometry>
        <sphere radius="0.02"/>
      </geometry>
    </visual>
    <collision>
      <geometry>
        <sphere radius="0.02"/>
      </geometry>
    </collision>
  </link>

  <joint name="RLeg_0" type="revolute">
    <parent link="HipsLink"/>
    <child link="torso2rleg_1"/>
    <origin rpy="0.0 0.0 0.0" xyz="-0.0 -0.1 -0.15"/>
    <axis xyz="1 0 0"/>
    <limit effort="100" lower="-0.87" upper="0.52" velocity="100"/>
  </joint>

  <joint name="RLeg_1" type="revolute">
    <parent link="torso2rleg_1"/>
    <child link="torso2rleg_2"/>
    <origin rpy="0.0 0.0 0.0" xyz="0.0 0.0 0.0"/>
    <axis xyz="0 1 0"/>
    <limit effort="100" lower="-2.3" upper="0.52" velocity="100"/>
  </joint>

  <joint name="RLeg_2" type="revolute">
    <parent link="torso2rleg_2"/>
    <child link="RLegLink"/>
    <origin rpy="0.0 0.0 0.0" xyz="0.0 0.0 0.0"/>
    <axis xyz="0 0 1"/>
    <limit effort="100" lower="-0.8" upper="0.8" velocity="100"/>
  </joint>


  <joint name="RShin_0" type="revolute">
    <parent link="RLegLink"/>
    <child link="RShinLink"/>
    <origin rpy="0.0 0.0 0.0" xyz="-0.025 0.0 -0.35"/>
    <axis xyz="0 1 0"/>
    <limit effort="100" lower="0.0" upper="2.6" velocity="100"/>
  </joint>

  <!-- Shin to right Ankle : 2DoF -->
  <link name="shin2rankle_1">
    <inertial>
      <origin rpy="0 0 0" xyz="0.0 0.0 0.0"/>
      <mass value="0.2"/>
      <inertia ixx="0.0000032" ixy="0.0" ixz="0.0" iyy="0.0000032" iyz="0.0" izz="0.0000032"/>
    </inertial>
    <visual>
      <geometry>
        <sphere radius="0.02"/>
      </geometry>
    </visual>
    <collision>
      <geometry>
        <sphere radius="0.02"/>
      </geometry>
    </collision>
  </link>

  <joint name="RAnkle_0" type="revolute">
    <parent link="RShinLink"/>
    <child link="shin2rankle_1"/>
    <origin rpy="0.0 0.0 0.0" xyz="-0.025 0.0 -0.375"/>
    <axis xyz="0 1 0"/>
    <limit effort="100" lower="-0.78" upper="1.3" velocity="100"/>
  </joint>

  <joint name="RAnkle_1" type="revolute">
    <parent link="shin2rankle_1"/>
    <child link="RAnkleLink"/>
    <origin rpy="0.0 0.0 0.0" xyz="0.0 0.0 0.0"/>
    <axis xyz="1 0 0"/>
    <limit effort="100" lower="-0.5" upper="0.5" velocity="100"/>
  </joint>

</robot>
